[2023-10-28T00:12:15.059+0000] {taskinstance.py:1159} INFO - Dependencies all met for dep_context=non-requeueable deps ti=<TaskInstance: swapi.load manual__2023-10-28T00:11:53.667476+00:00 [queued]>
[2023-10-28T00:12:15.274+0000] {taskinstance.py:1159} INFO - Dependencies all met for dep_context=requeueable deps ti=<TaskInstance: swapi.load manual__2023-10-28T00:11:53.667476+00:00 [queued]>
[2023-10-28T00:12:15.275+0000] {taskinstance.py:1361} INFO - Starting attempt 1 of 1
[2023-10-28T00:12:15.291+0000] {taskinstance.py:1382} INFO - Executing <Task(PythonOperator): load> on 2023-10-28 00:11:53.667476+00:00
[2023-10-28T00:12:15.305+0000] {standard_task_runner.py:57} INFO - Started process 81 to run task
[2023-10-28T00:12:15.311+0000] {standard_task_runner.py:84} INFO - Running: ['***', 'tasks', 'run', 'swapi', 'load', 'manual__2023-10-28T00:11:53.667476+00:00', '--job-id', '7', '--raw', '--subdir', 'DAGS_FOLDER/swapi/pipe/pipeline.py', '--cfg-path', '/tmp/tmpgz3gy_n7']
[2023-10-28T00:12:15.316+0000] {standard_task_runner.py:85} INFO - Job 7: Subtask load
[2023-10-28T00:12:15.399+0000] {task_command.py:416} INFO - Running <TaskInstance: swapi.load manual__2023-10-28T00:11:53.667476+00:00 [running]> on host ddb43e449d5d
[2023-10-28T00:12:15.484+0000] {taskinstance.py:1662} INFO - Exporting env vars: AIRFLOW_CTX_DAG_OWNER='Data Engineer' AIRFLOW_CTX_DAG_ID='swapi' AIRFLOW_CTX_TASK_ID='load' AIRFLOW_CTX_EXECUTION_DATE='2023-10-28T00:11:53.667476+00:00' AIRFLOW_CTX_TRY_NUMBER='1' AIRFLOW_CTX_DAG_RUN_ID='manual__2023-10-28T00:11:53.667476+00:00'
[2023-10-28T00:12:15.486+0000] {d03_load.py:25} INFO - Starting transform data to DW
[2023-10-28T00:12:15.547+0000] {taskinstance.py:1937} ERROR - Task failed with exception
Traceback (most recent call last):
  File "/home/airflow/.local/lib/python3.8/site-packages/airflow/operators/python.py", line 192, in execute
    return_value = self.execute_callable()
  File "/home/airflow/.local/lib/python3.8/site-packages/airflow/operators/python.py", line 209, in execute_callable
    return self.python_callable(*self.op_args, **self.op_kwargs)
  File "/opt/airflow/dags/swapi/dags/d03_load.py", line 50, in sw_work_to_dw
    sw.to_csv(f"{dw_path}{configs['dw']['dw_path']}", index=False)
  File "/home/airflow/.local/lib/python3.8/site-packages/pandas/core/generic.py", line 3772, in to_csv
    return DataFrameRenderer(formatter).to_csv(
  File "/home/airflow/.local/lib/python3.8/site-packages/pandas/io/formats/format.py", line 1186, in to_csv
    csv_formatter.save()
  File "/home/airflow/.local/lib/python3.8/site-packages/pandas/io/formats/csvs.py", line 240, in save
    with get_handle(
  File "/home/airflow/.local/lib/python3.8/site-packages/pandas/io/common.py", line 737, in get_handle
    check_parent_directory(str(handle))
  File "/home/airflow/.local/lib/python3.8/site-packages/pandas/io/common.py", line 600, in check_parent_directory
    raise OSError(rf"Cannot save file into a non-existent directory: '{parent}'")
OSError: Cannot save file into a non-existent directory: '/opt/***/data/swapi/gold'
[2023-10-28T00:12:15.570+0000] {taskinstance.py:1400} INFO - Marking task as FAILED. dag_id=swapi, task_id=load, execution_date=20231028T001153, start_date=20231028T001215, end_date=20231028T001215
[2023-10-28T00:12:15.587+0000] {standard_task_runner.py:104} ERROR - Failed to execute job 7 for task load (Cannot save file into a non-existent directory: '/opt/***/data/swapi/gold'; 81)
[2023-10-28T00:12:15.613+0000] {local_task_job_runner.py:228} INFO - Task exited with return code 1
[2023-10-28T00:12:15.653+0000] {taskinstance.py:2778} INFO - 0 downstream tasks scheduled from follow-on schedule check
